Traceback (most recent call last):
  File "/opt/hostedtoolcache/Python/3.7.15/x64/lib/python3.7/site-packages/jupyter_cache/executors/utils.py", line 56, in single_nb_execution
    record_timing=False,
  File "/opt/hostedtoolcache/Python/3.7.15/x64/lib/python3.7/site-packages/nbclient/client.py", line 1204, in execute
    return NotebookClient(nb=nb, resources=resources, km=km, **kwargs).execute()
  File "/opt/hostedtoolcache/Python/3.7.15/x64/lib/python3.7/site-packages/nbclient/util.py", line 84, in wrapped
    return just_run(coro(*args, **kwargs))
  File "/opt/hostedtoolcache/Python/3.7.15/x64/lib/python3.7/site-packages/nbclient/util.py", line 62, in just_run
    return loop.run_until_complete(coro)
  File "/opt/hostedtoolcache/Python/3.7.15/x64/lib/python3.7/asyncio/base_events.py", line 587, in run_until_complete
    return future.result()
  File "/opt/hostedtoolcache/Python/3.7.15/x64/lib/python3.7/site-packages/nbclient/client.py", line 664, in async_execute
    cell, index, execution_count=self.code_cells_executed + 1
  File "/opt/hostedtoolcache/Python/3.7.15/x64/lib/python3.7/site-packages/nbclient/client.py", line 965, in async_execute_cell
    await self._check_raise_for_error(cell, cell_index, exec_reply)
  File "/opt/hostedtoolcache/Python/3.7.15/x64/lib/python3.7/site-packages/nbclient/client.py", line 862, in _check_raise_for_error
    raise CellExecutionError.from_cell_and_msg(cell, exec_reply_content)
nbclient.exceptions.CellExecutionError: An error occurred while executing the following cell:
------------------
# define the path to the data
path_to_data = 'data/fdsreader/example_01/rundir'

sim = fdsreader.Simulation(path_to_data)
------------------

[0;31m---------------------------------------------------------------------------[0m
[0;31mOSError[0m                                   Traceback (most recent call last)
[0;32m/tmp/ipykernel_2412/2967051805.py[0m in [0;36m<module>[0;34m[0m
[1;32m      2[0m [0mpath_to_data[0m [0;34m=[0m [0;34m'data/fdsreader/example_01/rundir'[0m[0;34m[0m[0;34m[0m[0m
[1;32m      3[0m [0;34m[0m[0m
[0;32m----> 4[0;31m [0msim[0m [0;34m=[0m [0mfdsreader[0m[0;34m.[0m[0mSimulation[0m[0;34m([0m[0mpath_to_data[0m[0;34m)[0m[0;34m[0m[0;34m[0m[0m
[0m
[0;32m/opt/hostedtoolcache/Python/3.7.15/x64/lib/python3.7/site-packages/fdsreader/simulation.py[0m in [0;36m__new__[0;34m(cls, path)[0m
[1;32m     58[0m [0;34m[0m[0m
[1;32m     59[0m     [0;32mdef[0m [0m__new__[0m[0;34m([0m[0mcls[0m[0;34m,[0m [0mpath[0m[0;34m:[0m [0mstr[0m[0;34m)[0m[0;34m:[0m[0;34m[0m[0;34m[0m[0m
[0;32m---> 60[0;31m         [0msmv_file_path[0m [0;34m=[0m [0mget_smv_file[0m[0;34m([0m[0mpath[0m[0;34m)[0m[0;34m[0m[0;34m[0m[0m
[0m[1;32m     61[0m         [0mroot_path[0m [0;34m=[0m [0mos[0m[0;34m.[0m[0mpath[0m[0;34m.[0m[0mdirname[0m[0;34m([0m[0msmv_file_path[0m[0;34m)[0m[0;34m[0m[0;34m[0m[0m
[1;32m     62[0m [0;34m[0m[0m

[0;32m/opt/hostedtoolcache/Python/3.7.15/x64/lib/python3.7/site-packages/fdsreader/utils/data.py[0m in [0;36mget_smv_file[0;34m(path)[0m
[1;32m     95[0m         [0;32mreturn[0m [0mpath[0m [0;34m+[0m [0;34m".smv"[0m[0;34m[0m[0;34m[0m[0m
[1;32m     96[0m     [0;32melse[0m[0;34m:[0m[0;34m[0m[0;34m[0m[0m
[0;32m---> 97[0;31m         [0;32mraise[0m [0mIOError[0m[0;34m([0m[0;34m"The given path does neither point to a directory nor a file: "[0m [0;34m+[0m [0mpath[0m[0;34m)[0m[0;34m[0m[0;34m[0m[0m
[0m[1;32m     98[0m [0;34m[0m[0m
[1;32m     99[0m [0;34m[0m[0m

[0;31mOSError[0m: The given path does neither point to a directory nor a file: data/fdsreader/example_01/rundir
OSError: The given path does neither point to a directory nor a file: data/fdsreader/example_01/rundir

