Traceback (most recent call last):
  File "/opt/hostedtoolcache/Python/3.10.11/x64/lib/python3.10/site-packages/jupyter_cache/executors/utils.py", line 58, in single_nb_execution
    executenb(
  File "/opt/hostedtoolcache/Python/3.10.11/x64/lib/python3.10/site-packages/nbclient/client.py", line 1305, in execute
    return NotebookClient(nb=nb, resources=resources, km=km, **kwargs).execute()
  File "/opt/hostedtoolcache/Python/3.10.11/x64/lib/python3.10/site-packages/jupyter_core/utils/__init__.py", line 166, in wrapped
    return loop.run_until_complete(inner)
  File "/opt/hostedtoolcache/Python/3.10.11/x64/lib/python3.10/asyncio/base_events.py", line 649, in run_until_complete
    return future.result()
  File "/opt/hostedtoolcache/Python/3.10.11/x64/lib/python3.10/site-packages/nbclient/client.py", line 705, in async_execute
    await self.async_execute_cell(
  File "/opt/hostedtoolcache/Python/3.10.11/x64/lib/python3.10/site-packages/nbclient/client.py", line 1058, in async_execute_cell
    await self._check_raise_for_error(cell, cell_index, exec_reply)
  File "/opt/hostedtoolcache/Python/3.10.11/x64/lib/python3.10/site-packages/nbclient/client.py", line 914, in _check_raise_for_error
    raise CellExecutionError.from_cell_and_msg(cell, exec_reply_content)
nbclient.exceptions.CellExecutionError: An error occurred while executing the following cell:
------------------
data_root = root + 'data/pool_fire/1mw_sealed'
sim = fdsreader.Simulation(data_root)
slice_temp = sim.slices[0]
time = 20
time_index = slice_temp.get_nearest_timestep(time)

plt.figure(figsize=(4,6))
plt.imshow(slice_temp[0].data[time_index].T, origin='lower', 
           extent=slice_temp[0].extent.as_list(), cmap='jet',
           vmin=20, vmax=1200)
plt.xlabel("X / m")
plt.ylabel("Z / m")
plt.colorbar(label="Temperature / $\sf ^\circ C$")
plt.savefig('figs/pool_fire_1mw_temperatures_slice.svg', bbox_inches='tight')
plt.close()


------------------


[0;31m---------------------------------------------------------------------------[0m
[0;31mOSError[0m                                   Traceback (most recent call last)
Cell [0;32mIn[2], line 2[0m
[1;32m      1[0m data_root [38;5;241m=[39m root [38;5;241m+[39m [38;5;124m'[39m[38;5;124mdata/pool_fire/1mw_sealed[39m[38;5;124m'[39m
[0;32m----> 2[0m sim [38;5;241m=[39m [43mfdsreader[49m[38;5;241;43m.[39;49m[43mSimulation[49m[43m([49m[43mdata_root[49m[43m)[49m
[1;32m      3[0m slice_temp [38;5;241m=[39m sim[38;5;241m.[39mslices[[38;5;241m0[39m]
[1;32m      4[0m time [38;5;241m=[39m [38;5;241m20[39m

File [0;32m/opt/hostedtoolcache/Python/3.10.11/x64/lib/python3.10/site-packages/fdsreader/simulation.py:60[0m, in [0;36mSimulation.__new__[0;34m(cls, path)[0m
[1;32m     59[0m [38;5;28;01mdef[39;00m [38;5;21m__new__[39m([38;5;28mcls[39m, path: [38;5;28mstr[39m):
[0;32m---> 60[0m     smv_file_path [38;5;241m=[39m [43mget_smv_file[49m[43m([49m[43mpath[49m[43m)[49m
[1;32m     61[0m     root_path [38;5;241m=[39m os[38;5;241m.[39mpath[38;5;241m.[39mdirname(smv_file_path)
[1;32m     63[0m     [38;5;28;01mwith[39;00m [38;5;28mopen[39m(smv_file_path, [38;5;124m'[39m[38;5;124mr[39m[38;5;124m'[39m) [38;5;28;01mas[39;00m infile:

File [0;32m/opt/hostedtoolcache/Python/3.10.11/x64/lib/python3.10/site-packages/fdsreader/utils/data.py:92[0m, in [0;36mget_smv_file[0;34m(path)[0m
[1;32m     90[0m         [38;5;28;01mraise[39;00m [38;5;167;01mIOError[39;00m([38;5;124m"[39m[38;5;124mThere are multiple simulations in the directory: [39m[38;5;124m"[39m [38;5;241m+[39m path)
[1;32m     91[0m     [38;5;28;01melif[39;00m [38;5;28mlen[39m(files) [38;5;241m==[39m [38;5;241m0[39m:
[0;32m---> 92[0m         [38;5;28;01mraise[39;00m [38;5;167;01mIOError[39;00m([38;5;124m"[39m[38;5;124mNo simulations were found in the directory: [39m[38;5;124m"[39m [38;5;241m+[39m path)
[1;32m     93[0m     [38;5;28;01mreturn[39;00m files[[38;5;241m0[39m]
[1;32m     94[0m [38;5;28;01melif[39;00m os[38;5;241m.[39mpath[38;5;241m.[39misfile(path [38;5;241m+[39m [38;5;124m"[39m[38;5;124m.smv[39m[38;5;124m"[39m):

[0;31mOSError[0m: No simulations were found in the directory: ../../../../data/pool_fire/1mw_sealed

